Workbook

Sheet 名簿
A1: 児童名簿
A2: 姓 | B2: 名 | C2: セイ | D2: メイ | E2: 性別 | F2: 受給者番号 | G2: 障がい児支援区分
A3: 一戸 | B3: 竜太郎 | C3: イチノヘ | D3: リュウタロウ | E3: 男 | F3: 3980 | G3: 3

Sheet 記録表記載方法
A2: 【ルール】
A3: 施設到着～施設出発までの時間を記載
A4: 外出プログラムは開始地点～終了地点を決め、時間を記載
A5: 30分は1時間分で算定、当日中は合算時間。30分利用後中抜けして30分利用した場合は算定時間1時間となる
A6: 毎月10日に障がい福祉課に提出（10日が土日祝の場合は前日）
A7: 日中一時支援利用者証の利用者負担額（0円or18,600円）と障がい児区分(1～3）障がい者区分(1～6）を確認
A8: ＊障がい者の定義 18歳の誕生日月より
A9: 利用者負担額が上限を超える場合は、100％が市からの助成金となる。
A12: 算定時間の例）
A13: 利用時間 | C13: 算定時間
A14: 30分 | B14: → | C14: 1時間
A15: 1時間29分 | B15: → | C15: 1時間
A16: 1時間30分 | B16: → | C16: 2時間
A19: 【印鑑をもらう方法】
A20: 1ヵ月ごとにまとめて印鑑をもらう→当月最終利用日または、次月最初の利用日

Sheet 領収証
B1: 領収証
B4: 一戸竜太郎 | C4: 様
G5: ＮＩＣＯ Ｌｉｂｅｒｉ
G6: 浦安市猫実3-1-16
B7: 件名 | C7: ='集計'!$B$2 -> #REF! | G7: TEL 070-6977-0025
B8: 支援区分 | C8: 3 | G8: FAX 047-706-3956
B10: 合計金額 | D10: 221040 | F10: (税込)
D12: *利用助成金として浦安市から代理受領いたします
B14: 概要 | D14: 数量 | E14: 市請求額 | G14: 利用者負担
B15: 算定時間 | D15: 102 | E15: 206040 | G15: 0
B16: 送迎 | D16: 30 | E16: 15000 | G16: 0
B23: 領収証
B26: 田中 晧瑛 | C26: 様
G27: ＮＩＣＯ Ｌｉｂｅｒｉ
G28: 浦安市猫実3-1-16
B29: 件名 | C29: ='集計'!$B$2 -> #REF! | G29: TEL 070-6977-0025
B30: 支援区分 | C30: 3 | G30: FAX 047-706-3956
B32: 合計金額 | D32: 148014 | F32: (税込)
D34: *利用助成金として浦安市から代理受領いたします
B36: 概要 | D36: 数量 | E36: 市請求額 | G36: 利用者負担
B37: 算定時間 | D37: 73 | E37: =IF(C30=1,D37*1620*0.9,IF(C30=2,D37*1820*0.9,D37*2020*0.9)) -> 132714 | G37: 0
B38: 送迎 | D38: 34 | E38: =D38*500*0.9 -> 15300 | G38: 0
B45: 領収証
B48: 古賀丈太郎 | C48: 様
G49: ＮＩＣＯ Ｌｉｂｅｒｉ
G50: 浦安市猫実3-1-16
B51: 件名 | C51: ='集計'!$B$2 -> #REF! | G51: TEL 070-6977-0025
B52: 支援区分 | C52: 3 | G52: FAX 047-706-3956
B54: 合計金額 | D54: 81738 | F54: (税込)
D56: *利用助成金として浦安市から代理受領いたします
B58: 概要 | D58: 数量 | E58: 市請求額 | G58: 利用者負担
B59: 算定時間 | D59: 41 | E59: =IF(C52=1,D59*1620*0.9,IF(C52=2,D59*1820*0.9,D59*2020*0.9)) -> 74538 | G59: 0
B60: 送迎 | D60: 16 | E60: =D60*500*0.9 -> 7200 | G60: 0
B67: 領収証
B70: 北林 央睦 | C70: 様
G71: ＮＩＣＯ Ｌｉｂｅｒｉ
G72: 浦安市猫実3-1-16
B73: 件名 | C73: ='集計'!$B$2 -> #REF! | G73: TEL 070-6977-0025
B74: 支援区分 | C74: 3 | G74: FAX 047-706-3956
B76: 合計金額 | D76: 142614 | F76: (税込)
...

Sheet スケジュール表
A1: 令和8年1月 | B1: 1 | C1: 2 | D1: 3 | E1: 4 | F1: 5 | G1: 6 | H1: 7 | I1: 8 | J1: 9 | K1: 10 | L1: 11 | M1: 12 | N1: 13 | O1: 14 | P1: 15 | Q1: 16 | R1: 17 | S1: 18 | T1: 19 | U1: 20 | V1: 21 | W1: 22 | X1: 23 | Y1: 24 | Z1: 25 | AA1: 26 | AB1: 27 | AC1: 28 | AD1: 29 | AE1: 30 | AF1: 31
A2: 一戸竜太郎 | B2: 9:00-17:00 | F2: 10:00-17:00 | Q2: 15:30-17:40

Sheet テンプレート
S1: 日中一時支援事業サービス実績記録票
B2: 受給者証 番 号 | R2: 障がい児支援区分 及び障がい者支援区分 | AN2: 事業所名 | AU2: NICO Liberi
B4: 支給決定障害者等氏名
B8: 日付 | F8: 曜日 | J8: サービス提供実績 | V8: 算定 時間数 | AB8: 給付額 | AH8: 市請求額 | AN8: 利用者 負担額 | AT8: 利用者 確認印
J9: 開始 時間 | P9: 終了 時間
B29: 合計
AW30: 3 | AZ30: 枚中 | BC30: 1 | BF30: 枚
S32: 日中一時支援事業サービス実績記録票
B33: 受給者証 番 号 | R33: 障がい児支援区分 及び障がい者支援区分 | AN33: 事業所名 | AU33: NICO Liberi
B35: 支給決定障害者等氏名
B39: 日付 | F39: 曜日 | J39: サービス提供実績 | V39: 算定時間数 | AB39: 給付額 | AH39: 市請求額 | AN39: 利用者 負担額 | AT39: 利用者 確認印
J40: 開始時間 | P40: 終了時間
B59: 合計
AW61: 3 | AZ61: 枚中 | BC61: 2 | BF61: 枚
S62: 日中一時支援事業サービス実績記録票
B63: 受給者証 番 号 | R63: 障がい児支援区分 及び障がい者支援区分 | AN63: 事業所名 | AU63: NICO Liberi
B65: 支給決定障害者等氏名
B69: 日付 | F69: 曜日 | J69: サービス提供実績 | V69: 算定時間数 | AB69: 給付額 | AH69: 市請求額 | AN69: 利用者 負担額 | AT69: 利用者 確認印
J70: 開始時間 | P70: 終了時間
B90: 合計
AN91: .
AW92: 3 | AZ92: 枚中 | BC92: 3 | BF92: 枚

Sheet 一戸竜太郎
D1: 令和8年1月 | S1: 日中一時支援事業サービス実績記録票
B2: 受給者証 番 号 | H2: 3980 | R2: 障がい児支援区分 及び障がい者支援区分 | AC2: 障がい児支援区分3 | AN2: 事業所名 | AU2: NICO Liberi
B4: 支給決定障害者等氏名 | H4: 一戸竜太郎
B8: 日付 | F8: 曜日 | J8: サービス提供実績 | V8: 算定 時間数 | AB8: 給付額 | AH8: 市請求額 | AN8: 利用者 負担額 | AT8: 利用者 確認印
J9: 開始 時間 | P9: 終了 時間
B11: 1 | V11: 8 | AB11: =IF(V11="", "", V11 * 2020) -> 16160 | AH11: =IF(AB11="", "", AB11 - AN11) -> 14544 | AN11: =IF(AB11="", "", ROUNDDOWN(AB11 * 0.1,0)) -> 1616
B12: 〃 | V12: 0 | AB12: =IF(V12="", "", V12 * 2020) -> 0 | AH12: =IF(AB12="", "", AB12 - AN12) -> 0 | AN12: =IF(AB12="", "", ROUNDDOWN(AB12 * 0.1,0)) -> 0 | AZ12: 送迎
B13: 5 | V13: 7 | AB13: =IF(V13="", "", V13 * 2020) -> 14140 | AH13: =IF(AB13="", "", AB13 - AN13) -> 12726 | AN13: =IF(AB13="", "", ROUNDDOWN(AB13 * 0.1,0)) -> 1414
B14: 〃 | V14: 0 | AB14: =IF(V14="", "", V14 * 2020) -> 0 | AH14: =IF(AB14="", "", AB14 - AN14) -> 0 | AN14: =IF(AB14="", "", ROUNDDOWN(AB14 * 0.1,0)) -> 0 | AZ14: 送迎
B15: 16 | V15: 2 | AB15: =IF(V15="", "", V15 * 2020) -> 4040 | AH15: =IF(AB15="", "", AB15 - AN15) -> 3636 | AN15: =IF(AB15="", "", ROUNDDOWN(AB15 * 0.1,0)) -> 404
B16: 〃 | V16: 0 | AB16: =IF(V16="", "", V16 * 2020) -> 0 | AH16: =IF(AB16="", "", AB16 - AN16) -> 0 | AN16: =IF(AB16="", "", ROUNDDOWN(AB16 * 0.1,0)) -> 0 | AZ16: 送迎
AB17: =IF(V17="", "", V17 * 2020) | AH17: =IF(AB17="", "", AB17 - AN17) | AN17: =IF(AB17="", "", ROUNDDOWN(AB17 * 0.1,0))
AB18: =IF(V18="", "", V18 * 2020) | AH18: =IF(AB18="", "", AB18 - AN18) | AN18: =IF(AB18="", "", ROUNDDOWN(AB18 * 0.1,0))
AB19: =IF(V19="", "", V19 * 2020) | AH19: =IF(AB19="", "", AB19 - AN19) | AN19: =IF(AB19="", "", ROUNDDOWN(AB19 * 0.1,0))
AB20: =IF(V20="", "", V20 * 2020) | AH20: =IF(AB20="", "", AB20 - AN20) | AN20: =IF(AB20="", "", ROUNDDOWN(AB20 * 0.1,0))
AB21: =IF(V21="", "", V21 * 2020) | AH21: =IF(AB21="", "", AB21 - AN21) | AN21: =IF(AB21="", "", ROUNDDOWN(AB21 * 0.1,0))
AB22: =IF(V22="", "", V22 * 2020) | AH22: =IF(AB22="", "", AB22 - AN22) | AN22: =IF(AB22="", "", ROUNDDOWN(AB22 * 0.1,0))
AB23: =IF(V23="", "", V23 * 2020) | AH23: =IF(AB23="", "", AB23 - AN23) | AN23: =IF(AB23="", "", ROUNDDOWN(AB23 * 0.1,0))
AB24: =IF(V24="", "", V24 * 2020) | AH24: =IF(AB24="", "", AB24 - AN24) | AN24: =IF(AB24="", "", ROUNDDOWN(AB24 * 0.1,0))
AB25: =IF(V25="", "", V25 * 2020) | AH25: =IF(AB25="", "", AB25 - AN25) | AN25: =IF(AB25="", "", ROUNDDOWN(AB25 * 0.1,0))
AB26: =IF(V26="", "", V26 * 2020) | AH26: =IF(AB26="", "", AB26 - AN26) | AN26: =IF(AB26="", "", ROUNDDOWN(AB26 * 0.1,0))
AB27: =IF(V27="", "", V27 * 2020) | AH27: =IF(AB27="", "", AB27 - AN27) | AN27: =IF(AB27="", "", ROUNDDOWN(AB27 * 0.1,0))
AB28: =IF(V28="", "", V28 * 2020) | AH28: =IF(AB28="", "", AB28 - AN28) | AN28: =IF(AB28="", "", ROUNDDOWN(AB28 * 0.1,0))
B29: 合計 | AB29: =SUM(AB11:AB92) -> #REF! | AH29: =SUM(AH11:AH92) -> #REF! | AN29: =SUM(AN11:AN92) -> #REF!
AW30: 3 | AZ30: 枚中 | BC30: 1 | BF30: 枚
S32: 日中一時支援事業サービス実績記録票
B33: 受給者証 番 号 | H33: 3980 | R33: 障がい児支援区分 及び障がい者支援区分 | AC33: 障がい児支援区分3 | AN33: 事業所名 | AU33: NICO Liberi
B35: 支給決定障害者等氏名 | H35: 一戸竜太郎
B39: 日付 | F39: 曜日 | J39: サービス提供実績 | V39: 算定時間数 | AB39: 給付額 | AH39: 市請求額 | AN39: 利用者 負担額 | AT39: 利用者 確認印
J40: 開始時間 | P40: 終了時間
AB42: =IF(V42="", "", V42 * 2020) | AH42: =IF(AB42="", "", AB42 - AN42) | AN42: =IF(AB42="", "", ROUNDDOWN(AB42 * 0.1,0))
AB43: =IF(V43="", "", V43 * 2020) | AH43: =IF(AB43="", "", AB43 - AN43) | AN43: =IF(AB43="", "", ROUNDDOWN(AB43 * 0.1,0))
AB44: =IF(V44="", "", V44 * 2020) | AH44: =IF(AB44="", "", AB44 - AN44) | AN44: =IF(AB44="", "", ROUNDDOWN(AB44 * 0.1,0))
AB45: =IF(V45="", "", V45 * 2020) | AH45: =IF(AB45="", "", AB45 - AN45) | AN45: =IF(AB45="", "", ROUNDDOWN(AB45 * 0.1,0))
AB46: =IF(V46="", "", V46 * 2020) | AH46: =IF(AB46="", "", AB46 - AN46) | AN46: =IF(AB46="", "", ROUNDDOWN(AB46 * 0.1,0))
AB47: =IF(V47="", "", V47 * 2020) | AH47: =IF(AB47="", "", AB47 - AN47) | AN47: =IF(AB47="", "", ROUNDDOWN(AB47 * 0.1,0))
AB48: =IF(V48="", "", V48 * 2020) | AH48: =IF(AB48="", "", AB48 - AN48) | AN48: =IF(AB48="", "", ROUNDDOWN(AB48 * 0.1,0))
AB49: =IF(V49="", "", V49 * 2020) | AH49: =IF(AB49="", "", AB49 - AN49) | AN49: =IF(AB49="", "", ROUNDDOWN(AB49 * 0.1,0))
AB50: =IF(V50="", "", V50 * 2020) | AH50: =IF(AB50="", "", AB50 - AN50) | AN50: =IF(AB50="", "", ROUNDDOWN(AB50 * 0.1,0))
AB51: =IF(V51="", "", V51 * 2020) | AH51: =IF(AB51="", "", AB51 - AN51) | AN51: =IF(AB51="", "", ROUNDDOWN(AB51 * 0.1,0))
...
